Workbook

Sheet Cover Page
B2: GUI & FUNCTIONAL TEST CASES
B3: for <QUẢN LÝ BÁN HÀNG ONLINE>
B5: Document History – To maintain a list of changes being made
B6: Version | C6: Date | D6: Author | E6: Description of Changes
B7: <1.0> | C7: <8/10/2025> | D7: Phạm Ngọc Khôi Nguyên | E7: Test requirement và test case cho web admin (tất cả)
C8: <8/10/2025> | D8: Huỳnh Đăng Khoa | E8: Test requirement và test case cho web customer
C9: <8/10/2025> | D9: Nguyễn Minh Tâm | E9: test GUI
C10: <8/10/2025> | D10: Nguyễn Thị Bích Trâm | E10: test GUI
C11: <8/10/2025> | D11: Phạm Thị Hồng | E11: test GUI
B13: <1.1> | C13: <15/10/2025> | D13: Phạm Ngọc Khôi Nguyên | E13: Test requirement và test case cho web admin ( quản lý sản phẩm, đăng nhập admin, thêm/sửa danh mục, quản lý chương trình giảm) giá )
C14: <15/10/2025> | D14: Huỳnh Đăng Khoa | E14: Test requirement và test case cho web customer
C15: <15/10/2025> | D15: Nguyễn Minh Tâm | E15: test GUI và test case tương ứng ( xóa danh mục, quản lý màu sắc, quản lý đơn hàng )
C16: <15/10/2025> | D16: Nguyễn Thị Bích Trâm | E16: test GUI và test case tương ứng (quản lý coupon, quản lý gói thành viên, thông tin cá nhân)
C17: <15/10/2025> | D17: Phạm Thị Hồng | E17: test GUI
B19: <1.2> | C19: <25/10/2025> | D19: Phạm Ngọc Khôi Nguyên | E19: tiếp tục làm testcase
C20: <25/10/2025> | D20: Huỳnh Đăng Khoa | E20: tiếp tục làm testcase
C21: <25/10/2025> | D21: Nguyễn Minh Tâm | E21: tiếp tục làm testcase
C22: <25/10/2025> | D22: Nguyễn Thị Bích Trâm | E22: tiếp tục làm testcase
C23: <25/10/2025> | D23: Phạm Thị Hồng | E23: tiếp tục làm testcase
B25: <1.3> | C25: <11/11/2025> | D25: Phạm Ngọc Khôi Nguyên | E25: Execute Testing
C26: <11/11/2025> | D26: Huỳnh Đăng Khoa | E26: Execute Testing
C27: <11/11/2025> | D27: Nguyễn Minh Tâm | E27: Execute Testing
C28: <11/11/2025> | D28: Nguyễn Thị Bích Trâm | E28: Execute Testing
C29: <11/11/2025> | D29: Phạm Thị Hồng | E29: Execute Testing
B30: This document has been generated from template ST-FunctionalTestCase-Template, version 1.2
B32: Reference Documents – Clearly mark the document used as an input to create the test case
B33: Version | C33: Date | D33: Document Name
B34: <x.y> | C34: <dd-Mmm-yyyy>

Sheet Test Requirements AD
B1: List of Test Requirements
B2: No. | C2: Test Requirement ID | D2: Requirement Functions | E2: Mô tả chức năng | F2: Test Requirement Description | G2: Test Type | H2: Importance | I2: Status | J2: Number of TCs | K2: Note | L2: Test GUI | M2: Test Case | N2: Scenario
B3: 1 | C3: F1 | D3: Đăng nhập admin | E3: Đăng nhập vào hệ thống để quản lý | F3: Kiểm tra người dùng có thể đăng nhập được, đăng nhập không được, GUI | G3: Positive + Negative + LooknFeel | H3: High | I3: Complete | J3: =COUNTA('Test Cases AD'!$D$5:$D$29) -> 4 | L3: GUI ĐĂNG NHẬP ADMIN | M3: TC ĐĂNG NHẬP | N3: 1. Đăng nhập thành công với tài khoản hợp lệ 2. Đăng nhập thất bại với tài khoản không tồn tại 3. Đăng nhập thất bại với mật khẩu sai 4. Đăng nhập với trường bỏ trống 5. Kiểm tra giao diện trang đăng nhập (GUI)
B4: 2 | C4: F2 | D4: DashBoard | E4: Hiển thị thông tin tổng quan dựa trên vai trò người dùng | F4: Admin: Thấy tất cả thống kê tổng quan. Nhân viên: Chỉ thấy dữ liệu liên quan | G4: Positive + Negative | H4: High | I4: Complete | J4: =COUNTA('Test Cases AD'!$D$30:$D$64) -> 7 | M4: TC DASHBOARD | N4: 1. Admin xem đầy đủ tất cả thống kê tổng quan 2. Nhân viên chỉ thấy dữ liệu phạm vi được phép 3. Lọc dữ liệu theo ngày / 7 ngày / tháng 4. Làm mới dữ liệu dashboard 5. Xuất báo cáo từ dashboard
B5: 3 | C5: F3 | D5: Quản lý sản phẩm | E5: CRUD sản phẩm | F5: Kiểm tra chức năng quản lý toàn bộ sản phẩm (thêm, xem, sửa, xóa) | G5: Positive + Negative + LooknFeel | H5: High | I5: Complete | J5: =SUM(J6:J10) -> 66 | N5: 1. Thêm sản phẩm mới (thành công & thất bại) 2. Xem chi tiết sản phẩm 3. Sửa thông tin sản phẩm 4. Xóa sản phẩm 5. Tìm kiếm & lọc danh sách sản phẩm 6. Kiểm tra giao diện các màn hình quản lý SP
B6: 4 | C6: F3.1 | D6: Thêm sản phẩm | E6: Tạo sản phẩm mới | F6: Kiểm tra thêm sản phẩm thành công, thất bại, GUI | G6: Positive + Negative + LooknFeel | H6: High | I6: Complete | J6: =COUNTA('Test Cases AD'!$D$65:$D$382) -> 20 | L6: GUI THÊM SẢN PHẨM | M6: TC THÊM SẢN PHẨM | N6: 1. Thêm sản phẩm với đầy đủ thông tin hợp lệ 2. Thêm sản phẩm với tên trùng / để trống / vượt ký tự 3. Thêm sản phẩm với giá = 0, âm, không phải số 4. Upload ảnh sai định dạng / quá dung lượng / không có ảnh 5. Thêm sản phẩm không chọn danh mục / màu sắc 6. Thêm sản phẩm với số lượng tồn = 0 hoặc âm 7. Hủy thao tác thêm sản phẩm 8. Kiểm tra giao diện form thêm sản phẩm (GUI)
B7: 5 | C7: F3.2 | D7: Xem chi tiết sản phẩm | E7: Hiển thị thông tin SP | F7: Kiểm tra hiển thị đầy đủ thông tin chi tiết sản phẩm (hình ảnh, giá, thông số, đánh giá) | G7: Positive + Negative | H7: Medium | I7: Complete | J7: =COUNTA('Test Cases AD'!$D$383:$D$437) -> 11 | M7: TC XEM CHI TIẾT SẢN PHẨM | N7: 1. Xem chi tiết sản phẩm thành công với đầy đủ thông tin 2. Xem sản phẩm có nhiều hình ảnh / màu sắc 3. Xem sản phẩm không có mô tả / không có ảnh 4. Kiểm tra hiển thị định dạng giá, tồn kho, danh mục 5. Kiểm tra nút quay lại danh sách
B8: 6 | C8: F3.3 | D8: Xóa sản phẩm | E8: Xóa SP khỏi hệ thống | F8: Kiểm tra xóa sản phẩm thành công, thất bại và xác nhận trước khi xóa | G8: Positive + Negative | H8: Low | I8: Complete | J8: =COUNTA('Test Cases AD'!$D$438:$D$488) -> 9 | M8: TC XÓA SẢN PHẨM | N8: 1. Xóa sản phẩm thành công 2. Hủy thao tác xóa sản phẩm 3. Xóa sản phẩm đang có trong giỏ hàng / đơn hàng 4. Xóa sản phẩm có biến thể / đánh giá / khuyến mãi 5. Xóa sản phẩm khi không có quyền
B9: 7 | C9: F3.4 | D9: Sửa sản phẩm | E9: Cập nhật thông tin SP | F9: Kiểm tra cập nhật thông tin sản phẩm (giá, mô tả, hình ảnh, số lượng tồn kho) thành công, thất bại, GUI | G9: Positive + Negative + LooknFeel | H9: Medium | I9: Complete | J9: =COUNTA('Test Cases AD'!$D$489:$D$607) -> 13 | L9: GUI SỬA SẢN PHẨM | M9: TC SỬA SẢN PHẨM | N9: 1. Cập nhật thông tin cơ bản sản phẩm thành công 2. Validation: xóa trống tên, giá âm/0, số lượng âm 3. Thêm / xóa hình ảnh, không cho xóa ảnh cuối 4. Thêm / xóa biến thể màu sắc và cập nhật giá theo biến thể 5. Upload ảnh quá dung lượng 6. Cập nhật giá khuyến mãi theo thời gian 7. Kiểm tra giao diện form sửa sản phẩm (GUI)
B10: 8 | C10: F3.5 | D10: Xem danh sách sản phẩm | E10: Tìm và lọc sản phẩm theo filter | F10: Kiểm tra tìm kiếm theo tên, lọc theo giá, hãng, RAM, bộ nhớ, màu sắc | G10: Positive + Negative | H10: High | I10: Complete | J10: =COUNTA('Test Cases AD'!$D$608:$D$672) -> 13 | M10: TC XEM DANH SÁCH SẢN PHẨM | N10: 1. Tìm kiếm sản phẩm theo tên (chính xác / viết tắt / hoa-thường / có dấu) 2. Lọc theo hãng (một hãng / nhiều hãng) 3. Lọc theo khoảng giá 4. Sắp xếp theo giá tăng / giảm / tên A-Z / mới nhất / bán chạy 5. Tìm kiếm không có kết quả
B11: 9 | C11: F4 | D11: Quản lý danh mục | E11: CRUD danh mục | F11: Kiểm tra quản lý danh mục sản phẩm (iPhone, Samsung, Xiaomi, Oppo, v.v.) | G11: Positive + Negative + LooknFeel | H11: Medium | I11: Complete | J11: =SUM(J12:J15) -> 33 | N11: 1. Thêm danh mục mới (thành công & thất bại) 2. Sửa thông tin danh mục 3. Xóa danh mục 4. Xem danh sách và tìm kiếm danh mục 5. Kiểm tra giao diện các màn hình quản lý danh mục
B12: 10 | C12: F4.1 | D12: Thêm danh mục | E12: Tạo danh mục mới | F12: Kiểm tra thêm danh mục mới với tên và mô tả thành công, thất bại, GUI | G12: Positive + Negative + LooknFeel | H12: High | I12: Complete | J12: =COUNTA('Test Cases AD'!$D$673:$D$712) -> 8 | L12: GUI THÊM DANH MỤC | M12: TC THÊM DANH MỤC | N12: 1. Thêm danh mục với tên và mô tả hợp lệ 2. Thêm danh mục với tên trống / trùng lặp / vượt ký tự 3. Thêm danh mục với ký tự đặc biệt 4. Thêm danh mục chỉ có tên (không có mô tả) 5. Hủy thao tác thêm danh mục 6. Kiểm tra giao diện form thêm danh mục (GUI)
B13: 11 | C13: F4.2 | D13: Sửa danh mục | E13: Cập nhật danh mục | F13: Kiểm tra chỉnh sửa thông tin danh mục thành công, thất bại, GUI | G13: Positive + Negative + LooknFeel | H13: Medium | I13: Complete | J13: =COUNTA('Test Cases AD'!$D$713:$D$767) -> 11 | L13: GUI SỬA DANH MỤC | M13: TC SỬA DANH MỤC | N13: 1. Sửa tên và mô tả danh mục thành công 2. Sửa danh mục với tên trống / trùng / vượt ký tự / ký tự đặc biệt 3. Chỉ sửa mô tả, giữ nguyên tên cũ 4. Sửa danh mục đang được dùng bởi sản phẩm 5. Hủy thao tác sửa danh mục 6. Kiểm tra hiển thị dữ liệu cũ khi mở form sửa 7. Kiểm tra giao diện form sửa danh mục (GUI)
B14: 12 | C14: F4.3 | D14: Xóa danh mục | E14: Xóa danh mục | F14: Kiểm tra xóa danh mục thành công, thất bại và xử lý sản phẩm trong danh mục đó | G14: Positive + Negative | H14: Low | I14: Complete | J14: =COUNTA('Test Cases AD'!$D$768:$D$792) -> 5 | M14: TC XÓA DANH MỤC | N14: 1. Xóa danh mục không có sản phẩm thành công 2. Xóa danh mục đang có sản phẩm (xử lý ràng buộc) 3. Hủy thao tác xóa danh mục 4. Xóa danh mục với tài khoản không có quyền 5. Kiểm tra hiển thị thông tin xác nhận trước khi xóa
B15: 13 | C15: F4.4 | D15: Xem danh sách danh mục | E15: Hiển thị tất cả danh mục sản phẩm | F15: Kiểm tra danh sách các danh mục, lọc và tìm kiếm | G15: Positive + Negative | H15: High | I15: Complete | J15: =COUNTA('Test Cases AD'!$D$793:$D$837) -> 9 | M15: TC XEM DANH SÁCH DANH MỤC | N15: 1. Hiển thị danh sách tất cả danh mục và số SP trong từng danh mục 2. Tìm kiếm danh mục theo tên (tồn tại / không tồn tại / từ khóa trống) 3. Tìm kiếm với ký tự đặc biệt 4. Sắp xếp danh mục theo tên A-Z / số lượng sản phẩm 5. Hiển thị khi không có danh mục nào
B16: 14 | C16: F5 | D16: Quản lý màu sắc | E16: CRUD màu sắc | F16: Kiểm tra quản lý màu sắc điện thoại (đen, trắng, xanh, đỏ, v.v.) | G16: Positive + Negative + LooknFeel | H16: Low | I16: Complete | J16: =SUM(J17:J19) -> 33 | N16: 1. Thêm màu sắc mới (thành công & thất bại) 2. Sửa thông tin màu sắc 3. Xóa màu sắc 4. Kiểm tra giao diện các màn hình quản lý màu sắc
B17: 15 | C17: F5.1 | D17: Thêm màu sắc mới | E17: Tạo màu sắc mới | F17: Kiểm tra thêm tùy chọn màu sắc mới cho sản phẩm thành công, thất bại, GUI | G17: Positive + Negative + LooknFeel | H17: High | I17: Complete | J17: =COUNTA('Test Cases AD'!$D$838:$D$897) -> 12 | L17: GUI THÊM MÀU SẮC | M17: TC THÊM MÀU SẮC | N17: 1. Thêm màu sắc với tên và mã màu hợp lệ 2. Thêm màu sắc với tên có khoảng trắng / mã hex viết thường 3. Thêm màu sắc với tên trống / tên trùng lặp 4. Hủy thao tác thêm màu sắc 5. Kiểm tra giao diện form thêm màu sắc (GUI)
B18: 16 | C18: F5.2 | D18: Sửa màu sắc | E18: Cập nhật màu sắc | F18: Kiểm tra chỉnh sửa thông tin màu sắc thành công, thất bại, GUI | G18: Positive + Negative + LooknFeel | H18: Medium | I18: Complete | J18: =COUNTA('Test Cases AD'!$D$898:$D$977) -> 16 | L18: GUI SỬA MÀU SẮC | M18: TC SỬA MÀU SẮC | N18: 1. Sửa tên màu và mã màu thành công 2. Sửa màu sắc với tên trống / trùng lặp 3. Hủy thao tác sửa màu sắc 4. Kiểm tra hiển thị dữ liệu cũ khi mở form sửa 5. Kiểm tra giao diện form sửa màu sắc (GUI)
B19: 17 | C19: F5.3 | D19: Xóa màu sắc | E19: Xóa màu sắc | F19: Kiểm tra xóa màu sắc khỏi hệ thống thành công, thất bại | G19: Positive + Negative | H19: Low | I19: Complete | J19: =COUNTA('Test Cases AD'!$D$978:$D$1002) -> 5 | M19: TC XÓA MÀU SẮC | N19: 1. Xóa màu sắc không được dùng thành công 2. Xóa màu sắc đang được dùng bởi sản phẩm (xử lý ràng buộc) 3. Hủy thao tác xóa màu sắc
B20: 18 | C20: F6 | D20: Quản lý chương trình giảm giá | E20: CRUD khuyến mãi | F20: Kiểm tra quản lý các chương trình giảm giá theo % hoặc số tiền cố định | G20: Positive + Negative + LooknFeel | H20: High | I20: Complete | J20: =SUM(J21:J24) -> 52 | N20: 1. Thêm chương trình giảm giá mới (thành công & thất bại) 2. Sửa thông tin chương trình giảm giá 3. Xóa chương trình giảm giá 4. Xem danh sách chương trình giảm giá 5. Kiểm tra giao diện các màn hình quản lý giảm giá
B21: 19 | C21: F6.1 | D21: Thêm chương trình giảm giá | E21: Tạo CT khuyến mãi | F21: Kiểm tra tạo chương trình giảm giá với thời gian bắt đầu/kết thúc, điều kiện áp dụng thành công, thất bại, GUI | G21: Positive + Negative + LooknFeel | H21: High | I21: Complete | J21: =COUNTA('Test Cases AD'!$D$1003:$D$1077) -> 15 | L21: GUI THÊM CHƯƠNG TRÌNH GIẢM GIÁ | M21: TC THÊM CHƯƠNG TRÌNH GIẢM GIÁ | N21: 1. Tạo CT giảm giá theo % và số tiền cố định thành công 2. Thiết lập thời gian bắt đầu / kết thúc hợp lệ 3. Tạo CT với ngày kết thúc trước ngày bắt đầu 4. Tạo CT với điều kiện áp dụng hợp lệ / không hợp lệ 5. Tạo CT với % giảm > 100 hoặc âm 6. Hủy thao tác thêm chương trình giảm giá 7. Kiểm tra giao diện form thêm CT giảm giá (GUI)
B22: 20 | C22: F6.2 | D22: Sửa chương trình giảm giá | E22: Cập nhật CT khuyến mãi | F22: Kiểm tra chỉnh sửa thông tin chương trình khuyến mãi thành công, thất bại, GUI | G22: Positive + Negative + LooknFeel | H22: Medium | I22: Complete | J22: =COUNTA('Test Cases AD'!$D$1078:$D$1152) -> 15 | L22: GUI SỬA CHƯƠNG TRÌNH GIẢM GIÁ | M22: TC SỬA CHƯƠNG TRÌNH GIẢM GIÁ | N22: 1. Chỉnh sửa thông tin CT giảm giá thành công 2. Sửa CT đang hoạt động / đã hết hạn 3. Validation: thời gian, % giảm, điều kiện áp dụng không hợp lệ 4. Hủy thao tác sửa chương trình giảm giá 5. Kiểm tra giao diện form sửa CT giảm giá (GUI)
B23: 21 | C23: F6.3 | D23: Xóa chương trình giảm giá | E23: Xóa CT khuyến mãi | F23: Kiểm tra xóa chương trình giảm giá thành công, thất bại và xử lý đơn hàng đã áp dụng | G23: Positive + Negative | H23: Medium | I23: Complete | J23: =COUNTA('Test Cases AD'!$D$1153:$D$1187) -> 7 | M23: TC XÓA CHƯƠNG TRÌNH GIẢM GIÁ | N23: 1. Xóa CT giảm giá thành công 2. Xóa CT đang được áp dụng cho đơn hàng (xử lý ràng buộc) 3. Hủy thao tác xóa chương trình giảm giá 4. Kiểm tra thông báo xác nhận trước khi xóa
B24: 22 | C24: F6.4 | D24: Xem danh sách chương trình giảm giá | E24: Hiển thị tất cả chương trình giảm giá | F24: Kiểm tra danh sách, lọc và tìm kiếm | G24: Positive + Negative | H24: Low | I24: Complete | J24: =COUNTA('Test Cases AD'!$D$1188:$D$1262) -> 15 | M24: TC XEM DANH SÁCH CHƯƠNG TRÌNH GIẢM GIÁ | N24: 1. Hiển thị danh sách tất cả chương trình giảm giá 2. Lọc theo trạng thái (đang hoạt động / hết hạn / chưa bắt đầu) 3. Tìm kiếm CT giảm giá theo tên 4. Tìm kiếm không có kết quả
B25: 23 | C25: F7 | D25: Quản lý đơn hàng | E25: Xử lý đơn hàng | F25: Kiểm tra quản lý toàn bộ quy trình đơn hàng từ tạo đến hoàn thành | G25: Positive + Negative + LooknFeel | H25: High | I25: Complete | J25: =SUM(J26:J30) -> 77 | N25: 1. Tạo đơn hàng mới (thành công & thất bại) 2. Xem chi tiết đơn hàng 3. Sửa đơn hàng đang xử lý 4. Hủy đơn hàng 5. Xem danh sách và lọc đơn hàng 6. Kiểm tra giao diện các màn hình quản lý đơn hàng
B26: 24 | C26: F7.1 | D26: Tạo đơn hàng | E26: Tạo mới đon hàng | F26: Kiểm tra tạo đơn hàng thành công, thất bại, GUI | G26: Positive + Negative + LooknFeel | H26: High | I26: Complete | J26: =COUNTA('Test Cases AD'!$D$1263:$D$1395) -> 26 | L26: GUI TẠO ĐƠN HÀNG | M26: TC TẠO ĐƠN HÀNG | N26: 1. Tạo đơn hàng với sản phẩm và số lượng hợp lệ 2. Tạo đơn khi sản phẩm hết hàng hoặc không đủ số lượng 3. Áp dụng coupon / mã giảm giá khi tạo đơn 4. Tạo đơn với thông tin khách hàng không hợp lệ 5. Hủy thao tác tạo đơn hàng 6. Kiểm tra giao diện form tạo đơn hàng (GUI)
B27: 25 | C27: F7.2 | D27: Xem chi tiết đơn hàng | E27: Hiển thị chi tiết đơn hàng | F27: Kiểm tra hiển thị đầy đủ thông tin đơn hàng | G27: Positive + Negative | H27: Medium | I27: Complete | J27: 9 | M27: TC XEM CHI TIẾT ĐƠN HÀNG | N27: 1. Xem chi tiết đơn hàng với đầy đủ thông tin 2. Kiểm tra hiển thị trạng thái, sản phẩm, giá, khách hàng 3. Xem đơn hàng đã hủy / đã hoàn thành
B28: 26 | C28: F7.3 | D28: Sửa đơn hàng | E28: Sửa thông tin đơn hàng khi trạng thái đang xử lý | F28: Kiểm tra sửa thành công, thất bại , GUI | G28: Positive + Negative + LooknFeel | H28: Medium | I28: Complete | J28: =COUNTA('Test Cases AD'!$D$1447:$D$1551) -> 21 | L28: GUI SỬA ĐƠN HÀNG | M28: TC SỬA ĐƠN HÀNG | N28: 1. Sửa đơn hàng đang ở trạng thái 'đang xử lý' thành công 2. Sửa đơn hàng ở trạng thái không cho phép sửa 3. Validation: số lượng, sản phẩm không hợp lệ khi sửa 4. Hủy thao tác sửa đơn hàng 5. Kiểm tra giao diện form sửa đơn hàng (GUI)
B29: 27 | C29: F7.4 | D29: Hủy đơn hàng | E29: Huỷ đơn hàng | F29: Kiểm tra hủy đơn hàng thành công, thất bại | G29: Positive + Negative | H29: Medium | I29: Complete | J29: =COUNTA('Test Cases AD'!$D$1552:$D$1591) -> 8 | M29: TC HỦY ĐƠN HÀNG | N29: 1. Hủy đơn hàng đang xử lý thành công 2. Hủy đơn hàng đã hoàn thành / đã giao (không cho phép) 3. Hủy đơn hàng với lý do hợp lệ / để trống lý do 4. Kiểm tra hoàn trả tồn kho sau khi hủy
B30: 28 | C30: F7.5 | D30: Xem danh sách đơn hàng | E30: Xem danh sách đơn hàng | F30: Kiểm tra danh sách, lọc và tìm kiếm | G30: Positive + Negative | H30: Medium | I30: Complete | J30: =COUNTA('Test Cases AD'!$D$1592:$D$1656) -> 13 | M30: TC XEM DANH SÁCH ĐƠN HÀNG | N30: 1. Hiển thị danh sách tất cả đơn hàng 2. Lọc đơn hàng theo trạng thái / ngày / khách hàng 3. Tìm kiếm đơn hàng theo mã đơn 4. Tìm kiếm không có kết quả
B31: 29 | C31: F8 | D31: Quản lý khách hàng | E31: CRUD khách hàng | F31: Kiểm tra quản lý thông tin khách hàng (xem, chặn, xóa) | G31: Positive + Negative + LooknFeel | H31: Medium | I31: Complete | J31: =SUM(J32:J33) -> 14 | N31: 1. Xem danh sách khách hàng và lọc theo filter 2. Xem chi tiết thông tin khách hàng 3. Kiểm tra giao diện các màn hình quản lý khách hàng
B32: 30 | C32: F8.1 | D32: Xem danh sách khách hàng | E32: Tìm và lọc danh sách theo filter | F32: Kiểm tra hiển thị danh sách khách hàng, lọc tìm kiếm khách hàng | G32: Positive + Negative | H32: Medium | I32: Complete | J32: =COUNTA('Test Cases AD'!$D$1657:$D$1696) -> 8 | M32: TC XEM DANH SÁCH KHÁCH HÀNG | N32: 1. Hiển thị danh sách tất cả khách hàng 2. Tìm kiếm khách hàng theo tên / email / số điện thoại 3. Lọc khách hàng theo trạng thái (hoạt động / bị chặn) 4. Tìm kiếm không có kết quả
B33: 31 | C33: F8.2 | D33: Xem chi tiết khách hàng | E33: Hiển thị thông tin KH | F33: Kiểm tra xem thông tin chi tiết khách hàng thành công, thất bại | G33: Positive + Negative | H33: High | I33: Complete | J33: =COUNTA('Test Cases AD'!$D$1697:$D$1728) -> 6 | M33: TC XEM CHI TIẾT KHÁCH HÀNG | N33: 1. Xem chi tiết thông tin khách hàng thành công 2. Kiểm tra hiển thị lịch sử đơn hàng của khách 3. Xem chi tiết khách hàng không tồn tại 4. Kiểm tra quyền xem thông tin khách hàng
B34: 32 | C34: F9 | D34: Quản lý coupon | E34: CRUD mã giảm giá | F34: Kiểm tra quản lý mã coupon/voucher giảm giá | G34: Positive + Negative + LooknFeel | H34: High | I34: Complete | J34: =SUM(J35:J39) -> 56 | N34: 1. Xem danh sách coupon 2. Thêm coupon mới (thành công & thất bại) 3. Xem chi tiết coupon 4. Sửa thông tin coupon 5. Xóa coupon 6. Kiểm tra giao diện các màn hình quản lý coupon
B35: 33 | C35: F9.1 | D35: Xem danh sách coupon | E35: Tìm và lọc coupon theo filter | F35: Kiểm tra hiển thị danh sách các coupon và tìm kiếm lọc theo filter | G35: Positive + Negative | H35: High | I35: Complete | J35: =COUNTA('Test Cases AD'!$D$1729:$D$1753) -> 5 | M35: TC XEM DANH SÁCH COUPON | N35: 1. Hiển thị danh sách tất cả coupon 2. Tìm kiếm coupon theo mã / tên 3. Lọc coupon theo trạng thái (còn hiệu lực / hết hạn) 4. Tìm kiếm không có kết quả
B36: 34 | C36: F9.2 | D36: Thêm mới coupon | E36: Tạo mã giảm giá | F36: Kiểm tra tạo thành công, thất bại, GUI | G36: Positive + Negative + LooknFeel | H36: High | I36: Complete | J36: =COUNTA('Test Cases AD'!$D$1754:$D$1928) -> 19 | L36: GUI TẠO COUPON MỚI | M36: TC TẠO COUPON MỚI | N36: 1. Tạo coupon giảm giá theo % hoặc số tiền cố định thành công 2. Tạo coupon với mã bị trùng / để trống 3. Thiết lập ngày hết hạn hợp lệ / không hợp lệ 4. Giới hạn số lượt sử dụng hợp lệ / âm / = 0 5. Hủy thao tác tạo coupon 6. Kiểm tra giao diện form tạo coupon (GUI)
B37: 35 | C37: F9.3 | D37: Xem chi tiết coupon | E37: Hiển thị thông tin coupon | F37: Kiểm tra hiển thị thông tin chi tiết coupon và số lượt sử dụng | G37: Positive + Negative | H37: Medium | I37: Complete | J37: =COUNTA('Test Cases AD'!$D$1929:$D$1975) -> 9 | M37: TC XEM CHI TIẾT COUPON | N37: 1. Xem chi tiết coupon thành công với đầy đủ thông tin 2. Kiểm tra hiển thị số lượt sử dụng / còn lại 3. Xem coupon đã hết hạn / đã dùng hết lượt
B38: 36 | C38: F9.4 | D38: Sửa coupon | E38: Cập nhật coupon | F38: Kiểm tra chỉnh sửa thông tin coupon | G38: Positive + Negative + LooknFeel | H38: Medium | I38: Complete | J38: =COUNTA('Test Cases AD'!$D$1976:$D$2045) -> 14 | M38: TC SỬA COUPON | N38: 1. Chỉnh sửa thông tin coupon thành công 2. Sửa coupon đang được sử dụng / đã hết hạn 3. Validation: mã trùng, ngày không hợp lệ, giá trị âm 4. Hủy thao tác sửa coupon
B39: 37 | C39: F9.5 | D39: Xóa coupon | E39: Xóa coupon | F39: Kiểm tra xóa thành công, xóa thất bại | G39: Positive + Negative | H39: High | I39: Complete | J39: =COUNTA('Test Cases AD'!$D$2046:$D$2090) -> 9 | M39: TC XÓA COUPON | N39: 1. Xóa coupon chưa được sử dụng thành công 2. Xóa coupon đang được dùng trong đơn hàng 3. Hủy thao tác xóa coupon 4. Kiểm tra thông báo xác nhận trước khi xóa
B40: 42 | C40: F10 | D40: Quản lý phân quyền | E40: Phân quyền người dùng | F40: Kiểm tra phân quyền Admin, Staff, Customer với các chức năng tương ứng | G40: Positive + Negative + LooknFeel | H40: High | I40: Complete | J40: =SUM(J41:J43) -> 55 | N40: 1. Thêm quyền / role mới 2. Chỉnh sửa quyền của role 3. Xóa role và xử lý user đang có role đó 4. Kiểm tra phân quyền Admin / Staff / Customer 5. Kiểm tra giao diện các màn hình quản lý phân quyền
...

Sheet Test Cases AD
B1: Test Cases for 'Quản lý bán hàng online' function
O2: Execute Testing - Version1.0
B3: No. | C3: Test Requirement ID | D3: Test Case ID | E3: Test Objective | F3: Pre-conditions | G3: Step # | H3: Step Action | I3: Test Data | J3: Expected Result | K3: Actual | L3: Result | M3: Notes | N3: Type | O3: Result | P3: By tester | Q3: Note
B4: Functional TCs
B5: 1 | C5: F1 | O5: Passed | P5: Phạm Ngọc Khôi Nguyên
K8: Still on login page: http://localhost:5080/AdminAccount/Login | L8: Fail
K9: Still on login page: http://localhost:5080/AdminAccount/Login | L9: Fail
C10: BACK | D10: F1_01 | E10: Đăng nhập thành công | F10: Tài khoản đã được đăng ký trước đó | G10: 1 | H10: Mở trang đăng nhập | I10: http://localhost:5080/AdminAccount/Login | J10: Chuyển hướng đến trang admin: http://localhost:5080/Dashboard | K10: Chuyển hướng đến trang admin: http://localhost:5080/Dashboard | L10: Pass | N10: Functional - Valid | O10: Passed | P10: Phạm Ngọc Khôi Nguyên
G11: 2 | H11: Nhập tên đăng nhập hợp lệ | I11: admin1 | J11: Chuyển hướng đến trang admin: http://localhost:5080/Dashboard | K11: Chuyển hướng đến trang admin: http://localhost:5080/Dashboard | L11: Pass
G12: 3 | H12: Nhập mật khẩu hợp lệ | I12: 123 | J12: Chuyển hướng đến trang admin: http://localhost:5080/Dashboard | K12: Chuyển hướng đến trang admin: http://localhost:5080/Dashboard | L12: Pass
G13: 4 | H13: Click nút đăng nhập | J13: Chuyển hướng đến trang admin: http://localhost:5080/Dashboard | K13: Chuyển hướng đến trang admin: http://localhost:5080/Dashboard | L13: Pass
J14: Chuyển hướng đến trang admin: http://localhost:5080/Dashboard | K14: Chuyển hướng đến trang admin: http://localhost:5080/Dashboard | L14: Pass
D15: F1_02 | E15: Đăng nhập thất bại với tên tài khoản không tồn tại | F15: Không có | G15: 1 | H15: Mở trang đăng nhập | I15: http://localhost:5080/AdminAccount/Login | J15: Tên đăng nhập hoặc mật khẩu không đúng | K15: Tên đăng nhập hoặc mật khẩu không đúng | L15: Pass | N15: Functional - Invalid | O15: Passed | P15: Phạm Ngọc Khôi Nguyên
G16: 2 | H16: Nhập tên đăng nhập không tồn tại | I16: admin2 | K16: Tên đăng nhập hoặc mật khẩu không đúng | L16: Pass
G17: 3 | H17: Nhập mật khẩu bất kỳ | I17: 123 | K17: Tên đăng nhập hoặc mật khẩu không đúng | L17: Pass
G18: 4 | H18: Click nút đăng nhập | K18: Tên đăng nhập hoặc mật khẩu không đúng | L18: Pass
K19: Tên đăng nhập hoặc mật khẩu không đúng | L19: Pass
D20: F1_03 | E20: Đăng nhập thất bại với mật khẩu sai | F20: Tài khoản đã tồn tại | G20: 1 | H20: Mở trang đăng nhập | I20: http://localhost:5080/AdminAccount/Login | J20: Tên đăng nhập hoặc mật khẩu không đúng | K20: Tên đăng nhập hoặc mật khẩu không đúng | L20: Pass | N20: Functional - Invalid | O20: Passed | P20: Phạm Ngọc Khôi Nguyên
G21: 2 | H21: Nhập tên đăng nhập hợp lệ | I21: admin1 | K21: Tên đăng nhập hoặc mật khẩu không đúng | L21: Pass
G22: 3 | H22: Nhập mật khẩu sai | I22: 456 | K22: Tên đăng nhập hoặc mật khẩu không đúng | L22: Pass
G23: 4 | H23: Click nút đăng nhập | K23: Tên đăng nhập hoặc mật khẩu không đúng | L23: Pass
K24: Tên đăng nhập hoặc mật khẩu không đúng | L24: Pass
D25: F1_04 | E25: Đăng nhập với trường bỏ trống | F25: Không có | G25: 1 | H25: Mở trang đăng nhập | I25: http://localhost:5080/AdminAccount/Login | J25: Vui lòng nhập đầy đủ thông tin đăng nhập | K25: Vui lòng nhập đầy đủ thông tin đăng nhập | L25: Pass | N25: Functional - Invalid | O25: Passed | P25: Phạm Ngọc Khôi Nguyên
G26: 2 | H26: Để trống tên đăng nhập | J26: Vui lòng nhập đầy đủ thông tin đăng nhập | K26: Vui lòng nhập đầy đủ thông tin đăng nhập | L26: Pass
G27: 3 | H27: Để trống mật khẩu | J27: Vui lòng nhập đầy đủ thông tin đăng nhập | K27: Vui lòng nhập đầy đủ thông tin đăng nhập | L27: Pass
G28: 4 | H28: Click nút đăng nhập | J28: Vui lòng nhập đầy đủ thông tin đăng nhập | K28: Vui lòng nhập đầy đủ thông tin đăng nhập | L28: Pass
J29: Vui lòng nhập đầy đủ thông tin đăng nhập | K29: Vui lòng nhập đầy đủ thông tin đăng nhập | L29: Pass
B30: 3 | C30: F2 | D30: F2_01 | E30: Kiểm tra hiển thị dashboard chính xác với vai trò Admin | F30: Hệ thống đã có dữ liệu (ví dụ: 100 đơn hàng, 50.000.000đ tổng doanh thu) | G30: 1 | H30: Truy cập trang dashboard | J30: Hệ thống hiển thị trang Dashboard với đầy đủ các thông tin tổng quan của toàn hệ thống: | N30: Functional - Valid | O30: Passed | P30: Phạm Ngọc Khôi Nguyên
C35: BACK | D35: F2_02 | E35: Kiểm tra hiển thị dashboard chính xác với vai trò Nhân viên Bán hàng | F35: Có dữ liệu riêng (ví dụ: 10 đơn hàng đã xử lý, 5.000.000đ doanh số cá nhân). | G35: 1 | H35: Truy cập trang dashboard | J35: Hệ thống hiển thị trang Dashboard chỉ với các thông tin của nhanvien Không hiển thị các widget tổng quan của Admin (như "Tổng doanh thu toàn hệ thống") | N35: Functional - Valid | O35: Blocked | P35: Phạm Ngọc Khôi Nguyên
D40: F2_03 | E40: Lọc dữ liệu theo tháng | F40: Có dữ liệu trong tháng 10 | G40: 1 | H40: Click vào bộ lọc tháng | J40: Hiển thị thống kê trong tháng 10 | N40: Functional - Valid | O40: Blocked | P40: Phạm Ngọc Khôi Nguyên
G41: 2 | H41: Chọn tháng | I41: Tháng 10
D45: F2_04 | E45: Lọc dữ liệu theo 7 ngày gần nhất | F45: Có dữ liệu trong 7 ngày gần nhất | G45: 1 | H45: Click vào bộ lọc 7 ngày gần đây | J45: Hiển thị thống kê theo bộ lọc 7 ngày gần đây | N45: Functional - Valid | O45: Passed | P45: Phạm Ngọc Khôi Nguyên
D50: F2_05 | E50: Lọc dữ liệu theo ngày | F50: Có dữ liệu từ ngày 6/10/2055 - 10/10/2025 | G50: 1 | H50: Click vào bộ lọc ngày | J50: Hiển thị thống kê theo bộ lọc ngày | N50: Functional - Valid | O50: Blocked | P50: Phạm Ngọc Khôi Nguyên
G51: 2 | H51: Chọn ngày bắt đầu | I51: 45818
G52: 3 | H52: Chọn ngày kết thúc | I52: 45940
G53: 4 | H53: Click nút lọc
D55: F2_06 | E55: Làm mới dữ liệu dashboard | F55: Có nút refresh dữ liệu | G55: 1 | H55: Quan sát thời gian cập nhật cuối | J55: Hiển thị "last update: time" hiển thị thời gian hiện tại , icon xoay hiển thị loading, dữ liệu được cập nhật mới nhất | N55: Functional - Valid | O55: Blocked | P55: Phạm Ngọc Khôi Nguyên
G56: 2 | H56: Click nút "Refresh" hoặc icon làm mới
G57: 3 | H57: Chờ dữ liệu tải
G58: 4 | H58: Kiểm tra thời gian cập nhật
...

Sheet Test Requirements CUS
B1: List of Test Requirements
B2: No. | C2: Test Requirement ID | D2: Requirement Functions | E2: Mô tả chức năng | F2: Test Requirement Description | G2: Test Type | H2: Importance | I2: Status | J2: Number of TCs | K2: Note | L2: Test GUI | M2: Test Case | N2: Scenario
B3: 1 | C3: F1 | D3: Quản lý thông tin cá nhân | E3: Nhóm các chức năng về tài khoản người dùng | F3: Quản lý đăng nhập, đăng ký, đăng xuất đổi mật khẩu, quên mật khẩu, xem và cập nhậ thông tin cá nhân | G3: Postive +Negative | H3: High | I3: Pending | N3: 1. Đăng nhập tài khoản customer (thành công & thất bại) 2. Đăng ký tài khoản mới (thành công & thất bại) 3. Cập nhật mật khẩu (thành công & thất bại) 4. Quên mật khẩu và đặt lại qua email 5. Cập nhật thông tin cá nhân (tên, SĐT, năm sinh, địa chỉ) 6. Đăng xuất và kiểm tra hủy session
B4: 2 | C4: F1.1 | D4: Đăng nhập | E4: Người dùng đăng nhập hệ thống | F4: Kiểm tra người dùng đăng nhập thành công, thất bại, GUI | G4: Postive +Negative + LooknFeel | H4: High | I4: Pending | J4: =COUNTA('Test Cases CUS'!D5:D32) -> 7 | L4: GUI ĐĂNG NHẬP CUSTOMER | M4: TC ĐĂNG NHẬP | N4: 1. Đăng nhập thành công với tài khoản và mật khẩu đúng 2. Đăng nhập thất bại với email chưa được đăng ký 3. Đăng nhập thất bại với mật khẩu sai 4. Đăng nhập với trường Email bỏ trống 5. Đăng nhập với trường mật khẩu bỏ trống 6. Đăng nhập với cả hai trường đều bỏ trống 7. Kiểm tra giao diện trang đăng nhập (GUI)
B5: 3 | C5: F1.2 | D5: Đăng ký tài khoản | E5: Người dùng đăng ký tài khoản mới | F5: Kiểm tra việc tạo tài khoản thành công, thất bại , GUI | G5: Postive +Negative + LooknFeel | H5: High | I5: Pending | J5: =COUNTA('Test Cases CUS'!D33:D87) -> 7 | L5: GUI ĐĂNG KÝ CUSTOMER | M5: TC ĐĂNG KÝ | N5: 1. Đăng ký thành công với thông tin hợp lệ 2. Đăng ký thất bại với email đã tồn tại 3. Đăng ký thất bại với mật khẩu yếu / không đúng định dạng 4. Đăng ký thất bại với trường họ tên / email bỏ trống 5. Đăng ký thất bại khi mật khẩu xác nhận không khớp 6. Đăng ký thất bại khi không tích chấp nhận điều khoản 7. Kiểm tra giao diện trang đăng ký (GUI)
B6: 4 | C6: F1.3 | D6: Cập nhật mật khẩu | E6: Cho phép người dùng thay đổi mật khẩu hiện tại | F6: Kiểm tra người dùng cập nhật mật khẩu mới thành công, thất bại | G6: Postive +Negative | H6: Medium | I6: Pending | J6: =COUNTA('Test Cases CUS'!D88:D105) -> 3 | M6: TC CẬP NHẬT MẬT KHẨU | N6: 1. Cập nhật mật khẩu thành công với mật khẩu cũ đúng 2. Cập nhật thất bại với mật khẩu cũ không đúng 3. Cập nhật thất bại khi xác nhận mật khẩu mới không khớp 4. Cập nhật thất bại với mật khẩu mới quá yếu 5. Cập nhật với trường bỏ trống
B7: 5 | C7: F1.4 | D7: Quên mật khẩu | E7: Đặt lại mật khẩu | F7: Cho phép người dùng đặt lại mật khẩu qua email khi không nhớ mật khẩu cũ | G7: Postive +Negative | H7: Medium | I7: Pending | J7: =COUNTA('Test Cases CUS'!D106:D126) -> 3 | M7: TC QUÊN MẬT KHẨU | N7: 1. Đặt lại mật khẩu thành công với email hợp lệ đã đăng ký 2. Thất bại với email chưa được đăng ký 3. Thất bại khi xác nhận mật khẩu mới không khớp 4. Kiểm tra link đặt lại mật khẩu hết hạn 5. Kiểm tra trường email bỏ trống
B8: 7 | C8: F1.5 | D8: Cập nhật thông tin cá nhân | E8: Chỉnh sửa hồ sơ | F8: Kiểm tra cập nhật thông tin người dùng: tên, số điện thoại, năm sinh | G8: Postive +Negative | H8: Medium | I8: Pending | J8: =COUNTA('Test Cases CUS'!D127:D223) -> 20 | L8: GUI CẬP NHẬT THÔNG TIN CÁ NHÂN CUSTOMER | M8: TC CẬP NHẬT THÔNG TIN CÁ NHÂN | N8: 1. Cập nhật họ tên thành công (tên hợp lệ) 2. Cập nhật họ tên thất bại (để trống / quá ngắn / chứa số / ký tự đặc biệt) 3. Cập nhật số điện thoại thành công (10 số hợp lệ) 4. Cập nhật số điện thoại thất bại (sai định dạng / để trống / chứa ký tự đặc biệt) 5. Cập nhật năm sinh thành công (trong khoảng quy định) 6. Cập nhật năm sinh thất bại (thấp hơn / cao hơn / để trống) 7. Thêm địa chỉ giao hàng mới thành công 8. Thêm địa chỉ thất bại với trường bắt buộc để trống 9. Kiểm tra giao diện trang cập nhật thông tin cá nhân (GUI)
B9: 8 | C9: F1.6 | D9: Đăng xuất | E9: Thoát khỏi tài khoản | F9: Kiểm tra đăng xuất và xóa session người dùng | G9: Postive +Negative | H9: Medium | I9: Pending | J9: =COUNTA('Test Cases CUS'!D224:D235) -> 6 | M9: TC ĐĂNG XUẤT | N9: 1. Đăng xuất thành công từ trang cá nhân 2. Kiểm tra session bị hủy sau khi đăng xuất (nút Back) 3. Kiểm tra session bị hủy (truy cập URL trang cá nhân) 4. Đăng xuất khi đang có sản phẩm trong giỏ hàng 5. Hủy thao tác đăng xuất
B10: 9 | C10: F2 | D10: Quản lý giỏ hàng | E10: Nhóm chức năng về giỏ hàng | F10: Cho phép người dùng thêm, sửa, xoá sản phầm trong giỏ hàng | G10: Postive +Negative | H10: High | I10: Pending | N10: 1. Tìm kiếm và lọc sản phẩm 2. Xem chi tiết sản phẩm 3. Thêm sản phẩm vào giỏ hàng 4. Xem giỏ hàng 5. Xóa sản phẩm khỏi giỏ hàng 6. Sửa số lượng sản phẩm trong giỏ
B11: 10 | C11: F2.1 | D11: Tìm kiếm sản phẩm | E11: Người dùng tìm sản phẩm theo tên hoặc mã, tìm kiếm nâng cao (lọc theo giá, tên, danh mục…) | F11: Kiểm tra tìm kiếm sản phẩm thành công, thất bại | G11: Postive +Negative | H11: High | I11: Pending | J11: =COUNTA('Test Cases CUS'!D236:D255) -> 7 | M11: TC TÌM KIẾM SẢN PHẨM | N11: 1. Tìm kiếm sản phẩm theo tên thành công 2. Tìm kiếm không có kết quả phù hợp 3. Lọc sản phẩm theo giá tăng dần / giảm dần 4. Lọc sản phẩm theo tên A-Z / Z-A 5. Lọc theo danh mục sản phẩm
B12: 16 | C12: F2.2 | D12: Xem chi tiết sản phẩm | E12: Người dùng xem thông tin chi tiết sản phẩm | F12: Kiểm tra xem chi tiết sản phẩm thành công, thất bại | G12: Postive +Negative | H12: Medium | I12: Pending | J12: =COUNTA('Test Cases CUS'!D256:D285) -> 10 | M12: TC XEM CHI TIẾT SẢN PHẨM | N12: 1. Xem chi tiết sản phẩm còn hàng 2. Xem chi tiết sản phẩm đã hết hàng 3. Xem sản phẩm có khuyến mãi / giảm giá 4. Xem sản phẩm có nhiều biến thể (màu sắc, cấu hình) 5. Kiểm tra gallery hình ảnh phụ của sản phẩm 6. Kiểm tra hiển thị mô tả chi tiết và thông số kỹ thuật 7. Kiểm tra mục đánh giá / nhận xét của khách hàng 8. Kiểm tra mục sản phẩm liên quan 9. Truy cập sản phẩm không tồn tại
B13: 17 | C13: F2.3 | D13: Thêm sản phẩm vào giỏ hàng | E13: Người dùng thêm sản phẩm vào giỏ hàng | F13: Kiểm tra thêm sản phẩm vào giỏ hàng thành công, thất bại | G13: Postive +Negative | H13: Medium | I13: Pending | J13: =COUNTA('Test Cases CUS'!D286:D355) -> 14 | M13: TC THÊM SẢN PHẨM VÀO GIỎ HÀNG | N13: 1. Thêm 1 / nhiều sản phẩm còn hàng vào giỏ hàng rỗng 2. Thêm sản phẩm đã hết hàng (tồn kho = 0) 3. Thêm sản phẩm với số lượng vượt quá / bằng đúng tồn kho 4. Thêm sản phẩm với số lượng = 0, âm, không phải số 5. Thêm cùng 1 sản phẩm 2 lần (cập nhật số lượng) 6. Thêm sản phẩm khi SL mới + SL trong giỏ > tồn kho 7. Thêm sản phẩm khi chưa đăng nhập (Guest) 8. Thêm sản phẩm từ trang danh mục (Quick Add) 9. Thêm sản phẩm ở trạng thái 'Sắp ra mắt'
B14: 18 | C14: F2.4 | D14: Xem giỏ hàng | E14: Người dùng xem các sản phẩm trong giỏ | F14: Kiểm tra xem giỏ hàng thành công, thất bại | G14: Postive +Negative | H14: Medium | I14: Pending | J14: =COUNTA('Test Cases CUS'!D356:D395) -> 8 | M14: TC XEM GIỎ HÀNG | N14: 1. Xem giỏ hàng rỗng 2. Xem giỏ hàng có 1 / nhiều sản phẩm 3. Xem giỏ hàng của khách (Guest) 4. Kiểm tra hiển thị khi sản phẩm trong giỏ bị hết hàng 5. Kiểm tra hiển thị khi sản phẩm trong giỏ bị thay đổi giá 6. Kiểm tra gộp giỏ hàng khi Guest đăng nhập
B15: 19 | C15: F2.4.1 | D15: Xoá sản phẩm khỏi giỏ hàng | E15: Người dùng xoá sản phẩm không muốn mua | F15: Kiểm tra xóa sản phẩm khỏi giỏ hàng thành công, thất bại | G15: Postive +Negative | H15: Medium | I15: Pending | J15: =COUNTA('Test Cases CUS'!D396:D415) -> 5 | M15: TC XOÁ SẢN PHẨM KHỎI GIỎ HÀNG | N15: 1. Xóa 1 sản phẩm trong giỏ có nhiều sản phẩm 2. Xóa sản phẩm duy nhất trong giỏ (giỏ trở thành rỗng) 3. Hủy thao tác xóa (click Cancel) 4. Xóa sản phẩm khi chưa đăng nhập (Guest) 5. Xóa tất cả sản phẩm (nếu có chức năng 'Xóa tất cả')
B16: 20 | C16: F2.4.2 | D16: Sửa số lượng sản phẩm | E16: Người dùng tăng, giảm số lượng sản phẩm trong giỏ | F16: Kiểm tra tăng, giảm số lượng sản phẩm trong giỏ hàng thành công, thất bại | G16: Postive | H16: Medium | I16: Pending | J16: =COUNTA('Test Cases CUS'!D416:D447) -> 8 | M16: TC SỬA SỐ LƯỢNG SẢN PHẨM | N16: 1. Tăng số lượng sản phẩm hợp lệ (còn hàng) 2. Giảm số lượng sản phẩm hợp lệ 3. Tăng số lượng vượt quá tồn kho 4. Nhập trực tiếp số lượng vượt quá tồn kho 5. Giảm số lượng xuống 0 (bằng nút '-') 6. Nhập trực tiếp số lượng = 0 / âm / không phải số
B17: 21 | C17: F3 | D17: Theo dõi đơn hàng | E17: Cho phép người dùng theo dõi đơn hàng đã mua, mới mua, đang vận chuyển | F17: Kiểm tra danh sách đơn hàng đã mua, mới mua, đang vận chuyển, đã vận chuyển | G17: Postive +Negative | H17: Medium | I17: Pending | N17: 1. Xem danh sách đơn hàng (lọc, phân trang, tìm kiếm) 2. Xem chi tiết đơn hàng theo từng trạng thái 3. Hủy đơn hàng (thành công & không được phép)
B18: 22 | C18: F3.1 | D18: Xem danh sách đơn hàng | E18: Người dùng xem danh sách đơn hàng | F18: Kiểm tra xem danh sách đơn hàng thành công, thất bại, tìm kiếm nâng cao (theo trạng thái, ngày….) | G18: Postive +Negative | H18: High | I18: Pending | J18: =COUNTA('Test Cases CUS'!D448:D507) -> 15 | M18: TC XEM DANH SÁCH ĐƠN HÀNG | N18: 1. Hiển thị danh sách khi có nhiều / 1 / không có đơn hàng 2. Chặn truy cập khi chưa đăng nhập 3. Phân trang hoạt động chính xác 4. Lọc theo trạng thái (Đang xử lý / Đã giao / không có kết quả) 5. Tìm kiếm theo khoảng ngày hợp lệ / một ngày / ngày tương lai 6. Lỗi khi ngày 'Từ' > ngày 'Đến' / nhập ngày không hợp lệ 7. Tìm kiếm mã đơn hàng thành công / thất bại
B19: 23 | C19: F3.2 | D19: Xem chi tiết đơn hàng | E19: Người dùng xem chi tiết đơn hàng của mình | F19: Kiểm tra người dùng xem chi tiết đơn hàng thành công, thất bại | G19: Postive +Negative | H19: High | I19: Pending | J19: =COUNTA('Test Cases CUS'!D508:D528) -> 7 | M19: TC XEM CHI TIẾT ĐƠN HÀNG | N19: 1. Xem chi tiết đơn hàng ở trạng thái 'Đang xử lý' 2. Xem chi tiết đơn hàng ở trạng thái 'Đang giao' 3. Xem chi tiết đơn hàng ở trạng thái 'Đã giao' 4. Xem chi tiết đơn hàng ở trạng thái 'Đã hủy' 5. Truy cập chi tiết đơn hàng của người dùng khác (bảo mật) 6. Truy cập chi tiết đơn hàng không tồn tại 7. Truy cập khi chưa đăng nhập
B20: 22 | C20: F3.3 | D20: Hủy đơn hàng | E20: Người dùng đơn hàng khi còn ở trạng thái "Chờ xác nhận" | F20: Kiểm tra hủy thành công, không cho hủy khi đã xử lý | G20: Postive +Negative | H20: Medium | I20: Pending | J20: =COUNTA('Test Cases CUS'!D529:D556) -> 7 | M20: TC HỦY ĐƠN HÀNG | N20: 1. Hủy đơn hàng thành công khi ở trạng thái 'Chờ xác nhận' 2. Hủy thao tác xóa (click Cancel trên popup) 3. Không cho hủy khi đơn ở trạng thái 'Đang xử lý' 4. Không cho hủy khi đơn ở trạng thái 'Đang giao hàng' 5. Không cho hủy khi đơn ở trạng thái 'Đã giao hàng' 6. Không cho hủy đơn hàng đã bị hủy 7. Kiểm tra cập nhật trạng thái ở trang danh sách đơn hàng
B21: 24 | C21: F4 | D21: Mua hàng | E21: Mua sản phẩm | F21: Kiểm tra mua sản phẩm thành công, thất bại | G21: Postive +Negative | H21: High | I21: Pending | J21: =COUNTA('Test Cases CUS'!D557:D606) -> 8 | M21: TC MUA HÀNG | N21: 1. Mua hàng thành công với thanh toán COD 2. Mua hàng thành công với thẻ tín dụng hợp lệ 3. Thất bại khi bỏ trống trường bắt buộc 4. Thất bại khi thẻ tín dụng không hợp lệ (sai CVC) 5. Thất bại khi thẻ bị từ chối (không đủ tiền) 6. Xử lý khi sản phẩm hết hàng ngay trước khi đặt 7. Mua hàng với mã giảm giá / coupon hợp lệ 8. Mua hàng với mã giảm giá không hợp lệ / hết hạn
J22: =SUM(J3:J21) -> 135

Sheet Test Cases CUS
B1: Test Cases for 'Quản lý bán hàng online' function
N2: Execute Testing - Version1.0
B3: No. | C3: Test Requirement ID | D3: Test Case ID | E3: Test Objective | F3: Pre-conditions | G3: Step # | H3: Step Action | I3: Test Data | J3: Expected Result | K3: Actual | L3: Result | M3: Notes | N3: Result | O3: By tester | P3: Note | Q3: Type
B4: Functional TCs
B5: 1 | C5: F1.1 | D5: F1_00 | E5: Kiểm tra giao diện đăng nhập customer | F5: Vào được trang đăng nhập | G5: 1 | H5: Mở trang đăng nhập | J5: Giao diện được thiết kế đúng theo yêu cầu | N5: Passed | O5: Phạm Ngọc Khôi Nguyên | Q5: Non-Functional
G6: 2 | H6: Check giao diện theo form | I6: form đăng nhập
G7: 3 | H7: Check giao diện theo checklist | I7: checklist gui
C9: Back | D9: F1.1_01 | E9: Đăng nhập thành công với tài khoản và mật khẩu đúng | F9: Tài khoản đã được đăng ký trước đó | G9: 1 | H9: Mở trang đăng nhập | J9: Đăng nhập thành công chuyển hướng đến trang Admin | N9: Passed | O9: Phạm Ngọc Khôi Nguyên | Q9: Functional - Valid
G10: 2 | H10: Nhập email đăng nhập hợp lệ | I10: Nhutbudoppp@gmail.com | Q10: Functional - Valid
G11: 3 | H11: Nhập mật khẩu hợp lệ | I11: Nhut@2005 | Q11: Functional - Valid
G12: 4 | H12: Click nút đăng nhập | Q12: Functional - Valid
D13: F1.1_02 | E13: Đăng nhập thất bại với email chưa được đăng ký | F13: Không có | G13: 1 | H13: Mở trang đăng nhập | J13: Hiển thị thông báo tên đăng nhập hoặc mật khẩu không đúng | N13: Passed | O13: Phạm Ngọc Khôi Nguyên | Q13: Functional - Invalid
G14: 2 | H14: Nhập email đăng nhập không tồn tại | I14: mhnhwt@gmail.com | Q14: Functional - Invalid
G15: 3 | H15: Nhập mật khẩu bất kỳ | I15: 123456 | Q15: Functional - Invalid
G16: 4 | H16: Click nút đăng nhập | Q16: Functional - Invalid
D17: F1.1_03 | E17: Đăng nhập thất bại với mật khẩu sai | F17: Tài khoản đã tồn tại | G17: 1 | H17: Mở trang đăng nhập | J17: Hiển thị thông báo tên đăng nhập hoặc mật khẩu không đúng | N17: Passed | O17: Phạm Ngọc Khôi Nguyên | Q17: Functional - Invalid
G18: 2 | H18: Nhập tên đăng nhập hợp lệ | I18: Nhutbudoppp@gmail.com | Q18: Functional - Invalid
G19: 3 | H19: Nhập mật khẩu sai | I19: nhut123 | Q19: Functional - Invalid
G20: 4 | H20: Click nút đăng nhập | Q20: Functional - Invalid
D21: F1.1_04 | E21: Đăng nhập thất bại với trường Emai bỏ trống | F21: Không có | G21: 1 | H21: Mở trang đăng nhập | J21: Hiển thị thông báo vui lòng nhập email | N21: Passed | O21: Phạm Ngọc Khôi Nguyên | Q21: Functional - Invalid
G22: 2 | H22: Để trống email đăng nhập | Q22: Functional - Invalid
G23: 3 | H23: Nhập mật khẩu bất kỳ | I23: nhut123 | Q23: Functional - Invalid
G24: 4 | H24: Click nút đăng nhập | Q24: Functional - Invalid
D25: F1.1_05 | E25: Đăng nhập thất bại với trường mật khẩu bỏ trống | F25: Không có | G25: 1 | H25: Mở trang đăng nhập | J25: Hiển thị thông báo vui lòng nhập mật khẩu | N25: Passed | O25: Phạm Ngọc Khôi Nguyên | Q25: Functional - Invalid
G26: 2 | H26: Nhập emai đã được đăng ký | I26: Nhutbudoppp@gmail.com | Q26: Functional - Invalid
G27: 3 | H27: Bỏ trống mật khẩu | Q27: Functional - Invalid
G28: 4 | H28: Click nút đăng nhập | Q28: Functional - Invalid
D29: F1.1_06 | E29: Đăng nhập thất bại với trường email và mật khẩu bỏ trống | F29: Không có | G29: 1 | H29: Mở trang đăng nhập | J29: Hiển thị 2 thông báo yêu cầu nhập mật khẩu và email | N29: Passed | O29: Phạm Ngọc Khôi Nguyên | Q29: Functional - Invalid
G30: 2 | H30: Bỏ trống emai | Q30: Functional - Invalid
G31: 3 | H31: Bỏ trống mật khẩu | Q31: Functional - Invalid
G32: 4 | H32: Click nút đăng nhập | Q32: Functional - Invalid
B33: 2 | C33: F1.2 | D33: F1.2_01 | E33: Đăng ký thành công với thông tin hợp lệ | F33: Không có | G33: 1 | H33: Truy cập trang đăng ký | J33: Đăng ký thành công, chuyển hướng đến trang chủ | N33: Passed | O33: Phạm Ngọc Khôi Nguyên | Q33: Functional - Valid
G34: 2 | H34: Nhập họ | I34: Hoàng
G35: 3 | H35: Nhập tên | I35: Nhựt
G36: 4 | H36: Nhập email | I36: Nhutbudoppp@gmail.com
G37: 5 | H37: Nhập số điện thoại | I37: 0978782783
G38: 6 | H38: Nhập mật khẩu | I38: Nhut@2005
G39: 7 | H39: Xác nhận mât khẩu | I39: Nhut@2005
C40: Back | D40: F1.2_02 | E40: Đăng ký thất bại với email trùng | F40: Email đã tồn tại | G40: 1 | H40: Truy cập trang đăng ký | J40: Thông báo email đã tồn tại | N40: Passed | O40: Phạm Ngọc Khôi Nguyên | Q40: Functional - Invalid
G41: 2 | H41: Nhập họ | I41: Hoàng
...

Sheet Sheet2
A2: Priority | D2: Status | G2: Type
A3: High | D3: Not Executed | G3: LooknFeel
A4: Medium | D4: Passed | G4: Positive
A5: Low | D5: Failed | G5: Negative
G6: Boundary
